2025-06-05 16:01:05,509 - fire_safety - INFO - Request: GET http://127.0.0.1:8000/docs
2025-06-05 16:01:05,510 - fire_safety - INFO - Response: 200
2025-06-05 16:01:06,218 - fire_safety - INFO - Request: GET http://127.0.0.1:8000/openapi.json
2025-06-05 16:01:06,253 - fire_safety - INFO - Response: 200
2025-06-05 16:01:08,414 - fire_safety - INFO - Request: GET http://127.0.0.1:8000/docs
2025-06-05 16:01:08,415 - fire_safety - INFO - Response: 200
2025-06-05 16:01:08,555 - fire_safety - INFO - Request: GET http://127.0.0.1:8000/openapi.json
2025-06-05 16:01:08,556 - fire_safety - INFO - Response: 200
2025-06-05 16:01:30,400 - fire_safety - INFO - Request: GET http://127.0.0.1:8000/users/?skip=0&limit=100
2025-06-05 16:01:30,764 - fire_safety - INFO - Response: 200
2025-06-05 16:01:54,974 - fire_safety - INFO - Request: POST http://127.0.0.1:8000/token
2025-06-05 16:01:55,402 - fire_safety - INFO - Response: 200
2025-06-05 16:02:14,607 - fire_safety - INFO - Request: POST http://localhost:8000/token
2025-06-05 16:02:14,916 - fire_safety - INFO - Response: 200
2025-06-05 16:22:28,336 - fire_safety - INFO - Request: POST http://localhost:8000/register
2025-06-05 16:22:28,881 - fire_safety - INFO - Response: 200
2025-06-05 16:25:34,296 - fire_safety - INFO - Request: POST http://localhost:8000/validate-token
2025-06-05 16:25:34,299 - fire_safety - ERROR - Request failed: module 'auth' has no attribute 'verify_token'
Traceback (most recent call last):
  File "C:\Users\Roma\AppData\Local\Programs\Python\Python310\lib\site-packages\starlette\middleware\base.py", line 148, in call_next
    message = await recv_stream.receive()
  File "C:\Users\Roma\AppData\Local\Programs\Python\Python310\lib\site-packages\anyio\streams\memory.py", line 126, in receive
    raise EndOfStream from None
anyio.EndOfStream

During handling of the above exception, another exception occurred:

Traceback (most recent call last):
  File "C:\Users\Roma\Desktop\À–4 “Ãœ\main.py", line 332, in log_requests
    response = await call_next(request)
  File "C:\Users\Roma\AppData\Local\Programs\Python\Python310\lib\site-packages\starlette\middleware\base.py", line 156, in call_next
    raise app_exc
  File "C:\Users\Roma\AppData\Local\Programs\Python\Python310\lib\site-packages\starlette\middleware\base.py", line 141, in coro
    await self.app(scope, receive_or_disconnect, send_no_error)
  File "C:\Users\Roma\AppData\Local\Programs\Python\Python310\lib\site-packages\starlette\middleware\cors.py", line 85, in __call__
    await self.app(scope, receive, send)
  File "C:\Users\Roma\AppData\Local\Programs\Python\Python310\lib\site-packages\starlette\middleware\exceptions.py", line 62, in __call__
    await wrap_app_handling_exceptions(self.app, conn)(scope, receive, send)
  File "C:\Users\Roma\AppData\Local\Programs\Python\Python310\lib\site-packages\starlette\_exception_handler.py", line 53, in wrapped_app
    raise exc
  File "C:\Users\Roma\AppData\Local\Programs\Python\Python310\lib\site-packages\starlette\_exception_handler.py", line 42, in wrapped_app
    await app(scope, receive, sender)
  File "C:\Users\Roma\AppData\Local\Programs\Python\Python310\lib\site-packages\starlette\routing.py", line 714, in __call__
    await self.middleware_stack(scope, receive, send)
  File "C:\Users\Roma\AppData\Local\Programs\Python\Python310\lib\site-packages\starlette\routing.py", line 734, in app
    await route.handle(scope, receive, send)
  File "C:\Users\Roma\AppData\Local\Programs\Python\Python310\lib\site-packages\starlette\routing.py", line 288, in handle
    await self.app(scope, receive, send)
  File "C:\Users\Roma\AppData\Local\Programs\Python\Python310\lib\site-packages\starlette\routing.py", line 76, in app
    await wrap_app_handling_exceptions(app, request)(scope, receive, send)
  File "C:\Users\Roma\AppData\Local\Programs\Python\Python310\lib\site-packages\starlette\_exception_handler.py", line 53, in wrapped_app
    raise exc
  File "C:\Users\Roma\AppData\Local\Programs\Python\Python310\lib\site-packages\starlette\_exception_handler.py", line 42, in wrapped_app
    await app(scope, receive, sender)
  File "C:\Users\Roma\AppData\Local\Programs\Python\Python310\lib\site-packages\starlette\routing.py", line 73, in app
    response = await f(request)
  File "C:\Users\Roma\AppData\Local\Programs\Python\Python310\lib\site-packages\fastapi\routing.py", line 301, in app
    raw_response = await run_endpoint_function(
  File "C:\Users\Roma\AppData\Local\Programs\Python\Python310\lib\site-packages\fastapi\routing.py", line 214, in run_endpoint_function
    return await run_in_threadpool(dependant.call, **values)
  File "C:\Users\Roma\AppData\Local\Programs\Python\Python310\lib\site-packages\starlette\concurrency.py", line 37, in run_in_threadpool
    return await anyio.to_thread.run_sync(func)
  File "C:\Users\Roma\AppData\Local\Programs\Python\Python310\lib\site-packages\anyio\to_thread.py", line 56, in run_sync
    return await get_async_backend().run_sync_in_worker_thread(
  File "C:\Users\Roma\AppData\Local\Programs\Python\Python310\lib\site-packages\anyio\_backends\_asyncio.py", line 2470, in run_sync_in_worker_thread
    return await future
  File "C:\Users\Roma\AppData\Local\Programs\Python\Python310\lib\site-packages\anyio\_backends\_asyncio.py", line 967, in run
    result = context.run(func, *args)
  File "C:\Users\Roma\Desktop\À–4 “Ãœ\main.py", line 318, in validate_token
    email = auth.verify_token(token, credentials_exception)
AttributeError: module 'auth' has no attribute 'verify_token'
2025-06-05 16:25:34,372 - fire_safety - ERROR - Unhandled exception: module 'auth' has no attribute 'verify_token'
NoneType: None
2025-06-05 16:26:14,436 - fire_safety - INFO - Request: POST http://127.0.0.1:8000/token
2025-06-05 16:26:14,768 - fire_safety - INFO - Response: 200
2025-06-05 16:26:30,784 - fire_safety - INFO - Request: POST http://127.0.0.1:8000/refresh-token
2025-06-05 16:26:30,800 - fire_safety - ERROR - HTTPException: 401 - Invalid refresh token
2025-06-05 16:26:30,801 - fire_safety - INFO - Response: 401
2025-06-05 16:27:02,362 - fire_safety - INFO - Request: POST http://127.0.0.1:8000/validate-token
2025-06-05 16:27:02,366 - fire_safety - ERROR - Request failed: module 'auth' has no attribute 'verify_token'
Traceback (most recent call last):
  File "C:\Users\Roma\AppData\Local\Programs\Python\Python310\lib\site-packages\starlette\middleware\base.py", line 148, in call_next
    message = await recv_stream.receive()
  File "C:\Users\Roma\AppData\Local\Programs\Python\Python310\lib\site-packages\anyio\streams\memory.py", line 126, in receive
    raise EndOfStream from None
anyio.EndOfStream

During handling of the above exception, another exception occurred:

Traceback (most recent call last):
  File "C:\Users\Roma\Desktop\À–4 “Ãœ\main.py", line 332, in log_requests
    response = await call_next(request)
  File "C:\Users\Roma\AppData\Local\Programs\Python\Python310\lib\site-packages\starlette\middleware\base.py", line 156, in call_next
    raise app_exc
  File "C:\Users\Roma\AppData\Local\Programs\Python\Python310\lib\site-packages\starlette\middleware\base.py", line 141, in coro
    await self.app(scope, receive_or_disconnect, send_no_error)
  File "C:\Users\Roma\AppData\Local\Programs\Python\Python310\lib\site-packages\starlette\middleware\cors.py", line 93, in __call__
    await self.simple_response(scope, receive, send, request_headers=headers)
  File "C:\Users\Roma\AppData\Local\Programs\Python\Python310\lib\site-packages\starlette\middleware\cors.py", line 144, in simple_response
    await self.app(scope, receive, send)
  File "C:\Users\Roma\AppData\Local\Programs\Python\Python310\lib\site-packages\starlette\middleware\exceptions.py", line 62, in __call__
    await wrap_app_handling_exceptions(self.app, conn)(scope, receive, send)
  File "C:\Users\Roma\AppData\Local\Programs\Python\Python310\lib\site-packages\starlette\_exception_handler.py", line 53, in wrapped_app
    raise exc
  File "C:\Users\Roma\AppData\Local\Programs\Python\Python310\lib\site-packages\starlette\_exception_handler.py", line 42, in wrapped_app
    await app(scope, receive, sender)
  File "C:\Users\Roma\AppData\Local\Programs\Python\Python310\lib\site-packages\starlette\routing.py", line 714, in __call__
    await self.middleware_stack(scope, receive, send)
  File "C:\Users\Roma\AppData\Local\Programs\Python\Python310\lib\site-packages\starlette\routing.py", line 734, in app
    await route.handle(scope, receive, send)
  File "C:\Users\Roma\AppData\Local\Programs\Python\Python310\lib\site-packages\starlette\routing.py", line 288, in handle
    await self.app(scope, receive, send)
  File "C:\Users\Roma\AppData\Local\Programs\Python\Python310\lib\site-packages\starlette\routing.py", line 76, in app
    await wrap_app_handling_exceptions(app, request)(scope, receive, send)
  File "C:\Users\Roma\AppData\Local\Programs\Python\Python310\lib\site-packages\starlette\_exception_handler.py", line 53, in wrapped_app
    raise exc
  File "C:\Users\Roma\AppData\Local\Programs\Python\Python310\lib\site-packages\starlette\_exception_handler.py", line 42, in wrapped_app
    await app(scope, receive, sender)
  File "C:\Users\Roma\AppData\Local\Programs\Python\Python310\lib\site-packages\starlette\routing.py", line 73, in app
    response = await f(request)
  File "C:\Users\Roma\AppData\Local\Programs\Python\Python310\lib\site-packages\fastapi\routing.py", line 301, in app
    raw_response = await run_endpoint_function(
  File "C:\Users\Roma\AppData\Local\Programs\Python\Python310\lib\site-packages\fastapi\routing.py", line 214, in run_endpoint_function
    return await run_in_threadpool(dependant.call, **values)
  File "C:\Users\Roma\AppData\Local\Programs\Python\Python310\lib\site-packages\starlette\concurrency.py", line 37, in run_in_threadpool
    return await anyio.to_thread.run_sync(func)
  File "C:\Users\Roma\AppData\Local\Programs\Python\Python310\lib\site-packages\anyio\to_thread.py", line 56, in run_sync
    return await get_async_backend().run_sync_in_worker_thread(
  File "C:\Users\Roma\AppData\Local\Programs\Python\Python310\lib\site-packages\anyio\_backends\_asyncio.py", line 2470, in run_sync_in_worker_thread
    return await future
  File "C:\Users\Roma\AppData\Local\Programs\Python\Python310\lib\site-packages\anyio\_backends\_asyncio.py", line 967, in run
    result = context.run(func, *args)
  File "C:\Users\Roma\Desktop\À–4 “Ãœ\main.py", line 318, in validate_token
    email = auth.verify_token(token, credentials_exception)
AttributeError: module 'auth' has no attribute 'verify_token'
2025-06-05 16:27:02,377 - fire_safety - ERROR - Unhandled exception: module 'auth' has no attribute 'verify_token'
NoneType: None
2025-06-05 16:27:53,059 - fire_safety - INFO - Request: POST http://127.0.0.1:8000/refresh-token
2025-06-05 16:27:53,061 - fire_safety - INFO - Response: 422
